<?xml version="1.0"?>
<robot name="kit_c4">

  <!-- base_foot_print -->
  <link name="base_footprint"/>

  <!-- base_link -->
  <link name="base_link">
	<visual>
	  <geometry>
		<mesh filename="package://fourth_robot_description/meshes/DAE/body.dae" />
	  </geometry>
	</visual>
  </link>

  <joint name="base_footprint_to_base_link" type="fixed">
	<parent link="base_footprint"/>
	<child link="base_link"/>
	<origin rpy="0 0 0" xyz="0 0 0.20316"/>
  </joint>

  <!-- wheels -->
  <!-- right_wheel -->
  <link name="right_wheel">
	<visual>
	  <geometry>
		<mesh filename="package://fourth_robot_description/meshes/DAE/wheel.dae"/>
	  </geometry>
	</visual>
  </link>

  <joint name="base_link_to_right_wheel" type="continuous">
	<parent link="base_link"/>
	<child link="right_wheel"/>
	<origin rpy="0 0 0" xyz="0 -0.214375 0"/>
  </joint>

  <!-- left_wheel -->
  <link name="left_wheel">
	<visual>
	  <geometry>
		<mesh filename="package://fourth_robot_description/meshes/DAE/wheel.dae"/>
	  </geometry>
	</visual>
  </link>

  <joint name="base_link_to_left_wheel" type="continuous">
	<parent link="base_link"/>
	<child link="left_wheel"/>
	<origin rpy="0 0 3.141592" xyz="0 0.214375 0"/>
  </joint>

  <!-- sensors -->
  <!-- base_sensor -->
  <link name="base_sensor"/>

  <joint name="base_link_to_base_sensor" type="fixed">
	<parent link="base_link"/>
	<child link="base_sensor"/>
	<origin rpy="0 0 0" xyz="0 0 0"/>
  </joint>

  <!-- base_scan -->
  <link name="base_scan"/>

  <joint name="base_sensor_to_base_scan" type="fixed">
	<parent link="base_sensor"/>
	<child link="base_scan"/>
	<origin rpy="0 0 0" xyz="0 0 0"/>
  </joint>
  
  <!-- gps -->
  <link name="gps">
	<visual>
	  <geometry>
		<mesh filename="package://fourth_robot_description/meshes/DAE/gps.dae"/>
	  </geometry>
	</visual>
  </link>

  <joint name="base_sensor_to_gps" type="fixed">
	<parent link="base_sensor"/>
	<child link="gps"/>
	<origin rpy="0 0 -3.141592" xyz="-0.06229 0 0.420552"/>
  </joint>

  <!-- front_scan -->
  <link name="front_scan">
	<visual>
	  <geometry>
		<mesh filename="package://fourth_robot_description/meshes/DAE/front_lrf.dae"/>
	  </geometry>
	</visual>
  </link>

  <joint name="base_scan_to_front_scan" type="fixed">
	<parent link="base_scan"/>
	<child link="front_scan"/>
	<origin rpy="0 0 0 " xyz="0.208 0 -0.0282"/>
  </joint>

  <!-- rear_scan -->
  <link name="rear_scan">
	<visual>
	  <geometry>
		<mesh filename="package://fourth_robot_description/meshes/DAE/rear_lrf.dae"/>
	  </geometry>
	</visual>
  </link>

  <joint name="base_scan_to_rear_scan" type="fixed">
	<parent link="base_scan"/>
	<child link="rear_scan"/>
	<origin rpy="0 -3.141592 0" xyz="-0.452 0 -0.0309"/>
  </joint>

  <!-- gim30_scan -->
  <link name="gim30_scan">
	<visual>
	  <geometry>
		<mesh filename="package://fourth_robot_description/meshes/DAE/gim30.dae"/>
	  </geometry>
	</visual>
  </link>

  <joint name="base_scan_to_gim30_scan" type="fixed">
	<parent link="base_scan"/>
	<child link="gim30_scan"/>
	<origin rpy="0 0 0" xyz="0.12395931 0 0.24578237"/>
  </joint>

  
</robot>
