<?xml version="1.0"?>
<robot xmlns:xacro="http://ros.org/wiki/xacro">

  <xacro:include filename="$(find fourth_robot_description)/urdf/common.xacro"/>
  <xacro:include filename="$(find fourth_robot_description)/urdf/wheel/wheel.transmission.xacro"/>
  <xacro:include filename="$(find fourth_robot_description)/urdf/wheel/follow_wheel.gazebo.xacro"/>

  <xacro:property name="follow_wheel_radius" value="0.0135"/>
  <xacro:property name="follow_wheel_length" value="0.011"/>
  <xacro:property name="follow_wheel_mass" value="0.66"/>
  
  <xacro:macro name="follow_wheel_v0" params="prefix parent *joint_origin *joint_axis">
	<joint name="${prefix}_follow_wheel_joint" type="continuous">
	  <xacro:insert_block name="joint_origin"/>
	  <parent link="${parent}"/>
	  <child link="${prefix}_follow_wheel_link"/>
	  <xacro:insert_block name="joint_axis"/>
	</joint>

	<link name="${prefix}_follow_wheel_link">
<!--          <visual>
          <origin xyz="0 0 0" rpy="${-M_PI/2} 0 0"/>
		<geometry>
                  <cylinder radius="${follow_wheel_radius}" length="${follow_wheel_length}"/>
		</geometry>
	  </visual>-->
	  <collision>
                <origin xyz="0 0 0" rpy="${-M_PI/2} 0 0"/>
		<geometry>
		  <cylinder radius="${follow_wheel_radius}" length="${follow_wheel_length}"/>
		</geometry>
	  </collision>
	  <inertial>
		<origin xyz="0 -0.003 0" rpy="${-M_PI/2} 0 0"/>
		<cylinder_inertial mass="${follow_wheel_mass}"
						   radius="${follow_wheel_radius}" length="${follow_wheel_length}"/>
	  </inertial>
	</link>
  </xacro:macro>
  
</robot>
